<?xml version='1.0'?>
<sdf version='1.7'>
  <model name='myhexa'>
    <link name='base_link'>
      <inertial>
        <pose>0 0 0 0 -0 0</pose>
        <mass>2</mass>
        <inertia>
          <ixx>0.0347563</ixx>
          <ixy>0.000001</ixy>
          <ixz>0.000001</ixz>
          <iyy>0.0458929</iyy>
          <iyz>0.000001</iyz>
          <izz>0.0977</izz>
        </inertia>
      </inertial>
      <self_collide>0</self_collide>
      <enable_wind>0</enable_wind>
      <kinematic>0</kinematic>
      <pose>0 0 0 0 -0 0</pose>
      <visual name='base_link_inertia_visual'>
        <pose>0 0 0 0 -0 0</pose>
        <geometry>
          <mesh>
            <scale>1 1 1</scale>
            <uri>/home/usr/catkin_ws/src/uav_simulator/uav_gazebo/meshes/base_link.STL</uri>
          </mesh>
        </geometry>
        <material>
          <shader type='pixel'/>
        </material>
        <transparency>0</transparency>
        <cast_shadows>1</cast_shadows>
      </visual>
      <collision name='base_link_inertia_collision'>
        <laser_retro>0</laser_retro>
        <max_contacts>10</max_contacts>
        <pose>0 0 0 0 -0 0</pose>
        <geometry>
          <box>
            <size>0.6 0.6 0.2</size>
          </box>
        </geometry>
        <surface>
          <friction>
            <ode>
              <mu>1</mu>
              <mu2>1</mu2>
              <fdir1>0 0 0</fdir1>
              <slip1>0</slip1>
              <slip2>0</slip2>
            </ode>
            <torsional>
              <coefficient>1</coefficient>
              <patch_radius>0</patch_radius>
              <surface_radius>0</surface_radius>
              <use_patch_radius>1</use_patch_radius>
              <ode>
                <slip>0</slip>
              </ode>
            </torsional>
          </friction>
          <bounce>
            <restitution_coefficient>0</restitution_coefficient>
            <threshold>1e+06</threshold>
          </bounce>
          <contact>
            <collide_without_contact>0</collide_without_contact>
            <collide_without_contact_bitmask>1</collide_without_contact_bitmask>
            <collide_bitmask>1</collide_bitmask>
            <ode>
              <soft_cfm>0</soft_cfm>
              <soft_erp>0.2</soft_erp>
              <kp>1e+13</kp>
              <kd>1</kd>
              <max_vel>0.01</max_vel>
              <min_depth>0</min_depth>
            </ode>
            <bullet>
              <split_impulse>1</split_impulse>
              <split_impulse_penetration_threshold>-0.01</split_impulse_penetration_threshold>
              <soft_cfm>0</soft_cfm>
              <soft_erp>0.2</soft_erp>
              <kp>1e+13</kp>
              <kd>1</kd>
            </bullet>
          </contact>
        </surface>
      </collision>
    </link>

   
    <link name='rotor_1'>
      <pose>-0 0.28 0.026 0 -0 -0.5236</pose>
      <inertial>
        <pose>0 0 0 0 -0 0</pose>
        <mass>0.00492951</mass>
        <inertia>
          <ixx>9.61254e-07</ixx>
          <ixy>0</ixy>
          <ixz>0</ixz>
          <iyy>6.62936e-05</iyy>
          <iyz>0</iyz>
          <izz>6.71809e-05</izz>
        </inertia>
      </inertial>
      <self_collide>0</self_collide>
      <enable_wind>0</enable_wind>
      <kinematic>0</kinematic>
      <visual name='rotor_1_visual'>
        <pose>0 0 0.035 0 -0 0</pose>
        <geometry>
          <mesh>
            <scale>1 1 1</scale>
            <uri>/home/usr/catkin_ws/src/uav_simulator/uav_gazebo/meshes/rotor_1.STL</uri>
          </mesh>
        </geometry>
        <material>
          <script>
            <name>Gazebo/Red</name>
            <uri>file://media/materials/scripts/gazebo.material</uri>
          </script>
          <shader type='pixel'/>
        </material>
        <transparency>0</transparency>
        <cast_shadows>1</cast_shadows>
      </visual>
      <collision name='rotor_1_collision'>
        <laser_retro>0</laser_retro>
        <max_contacts>10</max_contacts>
        <pose>0 0 0 0 -0 0</pose>
        <geometry>
          <cylinder>
            <radius>0.127</radius>
            <length>0.005</length>
          </cylinder>
        </geometry>
        <surface>
          <friction>
            <ode>
              <mu>1</mu>
              <mu2>1</mu2>
              <fdir1>0 0 0</fdir1>
              <slip1>0</slip1>
              <slip2>0</slip2>
            </ode>
            <torsional>
              <coefficient>1</coefficient>
              <patch_radius>0</patch_radius>
              <surface_radius>0</surface_radius>
              <use_patch_radius>1</use_patch_radius>
              <ode>
                <slip>0</slip>
              </ode>
            </torsional>
          </friction>
          <bounce>
            <restitution_coefficient>0</restitution_coefficient>
            <threshold>1e+06</threshold>
          </bounce>
          <contact>
            <collide_without_contact>0</collide_without_contact>
            <collide_without_contact_bitmask>1</collide_without_contact_bitmask>
            <collide_bitmask>1</collide_bitmask>
            <ode>
              <soft_cfm>0</soft_cfm>
              <soft_erp>0.2</soft_erp>
              <kp>1e+13</kp>
              <kd>1</kd>
              <max_vel>0.01</max_vel>
              <min_depth>0</min_depth>
            </ode>
            <bullet>
              <split_impulse>1</split_impulse>
              <split_impulse_penetration_threshold>-0.01</split_impulse_penetration_threshold>
              <soft_cfm>0</soft_cfm>
              <soft_erp>0.2</soft_erp>
              <kp>1e+13</kp>
              <kd>1</kd>
            </bullet>
          </contact>
        </surface>
      </collision>
    </link>
    <link name='rotor_2'>
      <pose>-0 -0.28 0.026
       0 -0 -0.5236</pose>
      <inertial>
        <pose>0 0 0 0 -0 0</pose>
        <mass>0.00492951</mass>
        <inertia>
          <ixx>9.61254e-07</ixx>
          <ixy>0</ixy>
          <ixz>0</ixz>
          <iyy>6.62936e-05</iyy>
          <iyz>0</iyz>
          <izz>6.71809e-05</izz>
        </inertia>
      </inertial>
      <self_collide>0</self_collide>
      <enable_wind>0</enable_wind>
      <kinematic>0</kinematic>
      <visual name='rotor_2_visual'>
        <pose>0 0 0 0 -0 0</pose>
        <geometry>
          <mesh>
            <scale>1 1 1</scale>
            <uri>/home/usr/catkin_ws/src/uav_simulator/uav_gazebo/meshes/rotor_2.STL</uri>
          </mesh>
        </geometry>
        <material>
          <script>
            <name>Gazebo/Blue</name>
            <uri>file://media/materials/scripts/gazebo.material</uri>
          </script>
          <shader type='pixel'/>
        </material>
        <transparency>0</transparency>
        <cast_shadows>1</cast_shadows>
      </visual>
      <collision name='rotor_2_collision'>
        <laser_retro>0</laser_retro>
        <max_contacts>10</max_contacts>
        <pose>0 0 0 0 -0 0</pose>
        <geometry>
          <cylinder>
            <radius>0.127</radius>
            <length>0.005</length>
          </cylinder>
        </geometry>
        <surface>
          <friction>
            <ode>
              <mu>1</mu>
              <mu2>1</mu2>
              <fdir1>0 0 0</fdir1>
              <slip1>0</slip1>
              <slip2>0</slip2>
            </ode>
            <torsional>
              <coefficient>1</coefficient>
              <patch_radius>0</patch_radius>
              <surface_radius>0</surface_radius>
              <use_patch_radius>1</use_patch_radius>
              <ode>
                <slip>0</slip>
              </ode>
            </torsional>
          </friction>
          <bounce>
            <restitution_coefficient>0</restitution_coefficient>
            <threshold>1e+06</threshold>
          </bounce>
          <contact>
            <collide_without_contact>0</collide_without_contact>
            <collide_without_contact_bitmask>1</collide_without_contact_bitmask>
            <collide_bitmask>1</collide_bitmask>
            <ode>
              <soft_cfm>0</soft_cfm>
              <soft_erp>0.2</soft_erp>
              <kp>1e+13</kp>
              <kd>1</kd>
              <max_vel>0.01</max_vel>
              <min_depth>0</min_depth>
            </ode>
            <bullet>
              <split_impulse>1</split_impulse>
              <split_impulse_penetration_threshold>-0.01</split_impulse_penetration_threshold>
              <soft_cfm>0</soft_cfm>
              <soft_erp>0.2</soft_erp>
              <kp>1e+13</kp>
              <kd>1</kd>
            </bullet>
          </contact>
        </surface>
      </collision>
    </link>
    <link name='rotor_3'>
      <pose>-0.24249 -0.14 0.026 0 -0 -0.5236</pose>
      <inertial>
        <pose>0 0 0 0 -0 0</pose>
        <mass>0.00492951</mass>
        <inertia>
          <ixx>9.61254e-07</ixx>
          <ixy>0</ixy>
          <ixz>0</ixz>
          <iyy>6.62936e-05</iyy>
          <iyz>0</iyz>
          <izz>6.71809e-05</izz>
        </inertia>
      </inertial>
      <self_collide>0</self_collide>
      <enable_wind>0</enable_wind>
      <kinematic>0</kinematic>
      <visual name='rotor_3_visual'>
        <pose>0 0 0 0 -0 0</pose>
        <geometry>
          <mesh>
            <scale>1 1 1</scale>
            <uri>/home/usr/catkin_ws/src/uav_simulator/uav_gazebo/meshes/rotor_3.STL</uri>
          </mesh>
        </geometry>
        <material>
          <script>
            <name>Gazebo/Red</name>
            <uri>file://media/materials/scripts/gazebo.material</uri>
          </script>
          <shader type='pixel'/>
        </material>
        <transparency>0</transparency>
        <cast_shadows>1</cast_shadows>
      </visual>
      <collision name='rotor_3_collision'>
        <laser_retro>0</laser_retro>
        <max_contacts>10</max_contacts>
        <pose>0 0 0 0 -0 0</pose>
        <geometry>
          <cylinder>
            <radius>0.127</radius>
            <length>0.005</length>
          </cylinder>
        </geometry>
        <surface>
          <friction>
            <ode>
              <mu>1</mu>
              <mu2>1</mu2>
              <fdir1>0 0 0</fdir1>
              <slip1>0</slip1>
              <slip2>0</slip2>
            </ode>
            <torsional>
              <coefficient>1</coefficient>
              <patch_radius>0</patch_radius>
              <surface_radius>0</surface_radius>
              <use_patch_radius>1</use_patch_radius>
              <ode>
                <slip>0</slip>
              </ode>
            </torsional>
          </friction>
          <bounce>
            <restitution_coefficient>0</restitution_coefficient>
            <threshold>1e+06</threshold>
          </bounce>
          <contact>
            <collide_without_contact>0</collide_without_contact>
            <collide_without_contact_bitmask>1</collide_without_contact_bitmask>
            <collide_bitmask>1</collide_bitmask>
            <ode>
              <soft_cfm>0</soft_cfm>
              <soft_erp>0.2</soft_erp>
              <kp>1e+13</kp>
              <kd>1</kd>
              <max_vel>0.01</max_vel>
              <min_depth>0</min_depth>
            </ode>
            <bullet>
              <split_impulse>1</split_impulse>
              <split_impulse_penetration_threshold>-0.01</split_impulse_penetration_threshold>
              <soft_cfm>0</soft_cfm>
              <soft_erp>0.2</soft_erp>
              <kp>1e+13</kp>
              <kd>1</kd>
            </bullet>
          </contact>
        </surface>
      </collision>
    </link>
    <link name='rotor_4'>
      <pose>0.24249 0.14 0.026 0 -0 -0.5236</pose>
      <inertial>
        <pose>0 0 0 0 -0 0</pose>
        <mass>0.00492951</mass>
        <inertia>
          <ixx>9.61254e-07</ixx>
          <ixy>0</ixy>
          <ixz>0</ixz>
          <iyy>6.62936e-05</iyy>
          <iyz>0</iyz>
          <izz>6.71809e-05</izz>
        </inertia>
      </inertial>
      <self_collide>0</self_collide>
      <enable_wind>0</enable_wind>
      <kinematic>0</kinematic>
      <visual name='rotor_4_visual'>
        <pose>0 0 0 0 -0 0</pose>
        <geometry>
          <mesh>
            <scale>1 1 1</scale>
            <uri>/home/usr/catkin_ws/src/uav_simulator/uav_gazebo/meshes/rotor_4.STL</uri>
          </mesh>
        </geometry>
        <material>
          <script>
            <name>Gazebo/Red</name>
            <uri>file://media/materials/scripts/gazebo.material</uri>
          </script>
          <shader type='pixel'/>
        </material>
        <transparency>0</transparency>
        <cast_shadows>1</cast_shadows>
      </visual>
      <collision name='rotor_4_collision'>
        <laser_retro>0</laser_retro>
        <max_contacts>10</max_contacts>
        <pose>0 0 0 0 -0 0</pose>
        <geometry>
          <cylinder>
            <radius>0.127</radius>
            <length>0.005</length>
          </cylinder>
        </geometry>
        <surface>
          <friction>
            <ode>
              <mu>1</mu>
              <mu2>1</mu2>
              <fdir1>0 0 0</fdir1>
              <slip1>0</slip1>
              <slip2>0</slip2>
            </ode>
            <torsional>
              <coefficient>1</coefficient>
              <patch_radius>0</patch_radius>
              <surface_radius>0</surface_radius>
              <use_patch_radius>1</use_patch_radius>
              <ode>
                <slip>0</slip>
              </ode>
            </torsional>
          </friction>
          <bounce>
            <restitution_coefficient>0</restitution_coefficient>
            <threshold>1e+06</threshold>
          </bounce>
          <contact>
            <collide_without_contact>0</collide_without_contact>
            <collide_without_contact_bitmask>1</collide_without_contact_bitmask>
            <collide_bitmask>1</collide_bitmask>
            <ode>
              <soft_cfm>0</soft_cfm>
              <soft_erp>0.2</soft_erp>
              <kp>1e+13</kp>
              <kd>1</kd>
              <max_vel>0.01</max_vel>
              <min_depth>0</min_depth>
            </ode>
            <bullet>
              <split_impulse>1</split_impulse>
              <split_impulse_penetration_threshold>-0.01</split_impulse_penetration_threshold>
              <soft_cfm>0</soft_cfm>
              <soft_erp>0.2</soft_erp>
              <kp>1e+13</kp>
              <kd>1</kd>
            </bullet>
          </contact>
        </surface>
      </collision>
    </link>
    <link name='rotor_5'>
      <pose>-0.24249 0.14 0.026 0 -0 -0.5236</pose>
      <inertial>
        <pose>0 0 0 0 -0 0</pose>
        <mass>0.00492951</mass>
        <inertia>
          <ixx>9.61254e-07</ixx>
          <ixy>0</ixy>
          <ixz>0</ixz>
          <iyy>6.62936e-05</iyy>
          <iyz>0</iyz>
          <izz>6.71809e-05</izz>
        </inertia>
      </inertial>
      <self_collide>0</self_collide>
      <enable_wind>0</enable_wind>
      <kinematic>0</kinematic>
      <visual name='rotor_5_visual'>
        <pose>0 0 0 0 -0 0</pose>
        <geometry>
          <mesh>
            <scale>1 1 1</scale>
            <uri>/home/usr/catkin_ws/src/uav_simulator/uav_gazebo/meshes/rotor_5.STL</uri>
          </mesh>
        </geometry>
        <material>
          <script>
            <name>Gazebo/Blue</name>
            <uri>file://media/materials/scripts/gazebo.material</uri>
          </script>
          <shader type='pixel'/>
        </material>
        <transparency>0</transparency>
        <cast_shadows>1</cast_shadows>
      </visual>
      <collision name='rotor_5_collision'>
        <laser_retro>0</laser_retro>
        <max_contacts>10</max_contacts>
        <pose>0 0 0 0 -0 0</pose>
        <geometry>
          <cylinder>
            <radius>0.127</radius>
            <length>0.005</length>
          </cylinder>
        </geometry>
        <surface>
          <friction>
            <ode>
              <mu>1</mu>
              <mu2>1</mu2>
              <fdir1>0 0 0</fdir1>
              <slip1>0</slip1>
              <slip2>0</slip2>
            </ode>
            <torsional>
              <coefficient>1</coefficient>
              <patch_radius>0</patch_radius>
              <surface_radius>0</surface_radius>
              <use_patch_radius>1</use_patch_radius>
              <ode>
                <slip>0</slip>
              </ode>
            </torsional>
          </friction>
          <bounce>
            <restitution_coefficient>0</restitution_coefficient>
            <threshold>1e+06</threshold>
          </bounce>
          <contact>
            <collide_without_contact>0</collide_without_contact>
            <collide_without_contact_bitmask>1</collide_without_contact_bitmask>
            <collide_bitmask>1</collide_bitmask>
            <ode>
              <soft_cfm>0</soft_cfm>
              <soft_erp>0.2</soft_erp>
              <kp>1e+13</kp>
              <kd>1</kd>
              <max_vel>0.01</max_vel>
              <min_depth>0</min_depth>
            </ode>
            <bullet>
              <split_impulse>1</split_impulse>
              <split_impulse_penetration_threshold>-0.01</split_impulse_penetration_threshold>
              <soft_cfm>0</soft_cfm>
              <soft_erp>0.2</soft_erp>
              <kp>1e+13</kp>
              <kd>1</kd>
            </bullet>
          </contact>
        </surface>
      </collision>
    </link>
    <link name='rotor_6'>
      <pose>0.24249 -0.14 0.026 0 -0 -0.5236</pose>
      <inertial>
        <pose>0 0 0 0 -0 0</pose>
        <mass>0.00492951</mass>
        <inertia>
          <ixx>9.61254e-07</ixx>
          <ixy>0</ixy>
          <ixz>0</ixz>
          <iyy>6.62936e-05</iyy>
          <iyz>0</iyz>
          <izz>6.71809e-05</izz>
        </inertia>
      </inertial>
      <self_collide>0</self_collide>
      <enable_wind>0</enable_wind>
      <kinematic>0</kinematic>
      <visual name='rotor_6_visual'>
        <pose>0 0 0 0 -0 0</pose>
        <geometry>
          <mesh>
            <scale>1 1 1</scale>
            <uri>/home/usr/catkin_ws/src/uav_simulator/uav_gazebo/meshes/rotor_6.STL</uri>
          </mesh>
        </geometry>
        <material>
          <script>
            <name>Gazebo/Blue</name>
            <uri>file://media/materials/scripts/gazebo.material</uri>
          </script>
          <shader type='pixel'/>
        </material>
        <transparency>0</transparency>
        <cast_shadows>1</cast_shadows>
      </visual>
      <collision name='rotor_6_collision'>
        <laser_retro>0</laser_retro>
        <max_contacts>10</max_contacts>
        <pose>0 0 0 0 -0 0</pose>
        <geometry>
          <cylinder>
            <radius>0.127</radius>
            <length>0.005</length>
          </cylinder>
        </geometry>
        <surface>
          <friction>
            <ode>
              <mu>1</mu>
              <mu2>1</mu2>
              <fdir1>0 0 0</fdir1>
              <slip1>0</slip1>
              <slip2>0</slip2>
            </ode>
            <torsional>
              <coefficient>1</coefficient>
              <patch_radius>0</patch_radius>
              <surface_radius>0</surface_radius>
              <use_patch_radius>1</use_patch_radius>
              <ode>
                <slip>0</slip>
              </ode>
            </torsional>
          </friction>
          <bounce>
            <restitution_coefficient>0</restitution_coefficient>
            <threshold>1e+06</threshold>
          </bounce>
          <contact>
            <collide_without_contact>0</collide_without_contact>
            <collide_without_contact_bitmask>1</collide_without_contact_bitmask>
            <collide_bitmask>1</collide_bitmask>
            <ode>
              <soft_cfm>0</soft_cfm>
              <soft_erp>0.2</soft_erp>
              <kp>1e+13</kp>
              <kd>1</kd>
              <max_vel>0.01</max_vel>
              <min_depth>0</min_depth>
            </ode>
            <bullet>
              <split_impulse>1</split_impulse>
              <split_impulse_penetration_threshold>-0.01</split_impulse_penetration_threshold>
              <soft_cfm>0</soft_cfm>
              <soft_erp>0.2</soft_erp>
              <kp>1e+13</kp>
              <kd>1</kd>
            </bullet>
          </contact>
        </surface>
      </collision>
    </link>


    <link name='imu_link'>
      <pose>0 0 0 0 0 3.1415927</pose>
      <inertial>
        <pose>0 0 0 0 0 0</pose>
        <mass>0.015</mass>
        <inertia>
          <ixx>1e-05</ixx>
          <ixy>0</ixy>
          <ixz>0</ixz>
          <iyy>1e-05</iyy>
          <iyz>0</iyz>
          <izz>1e-05</izz>
        </inertia>
      </inertial>
      <sensor name="imu_sensor" type="imu">
        <pose>0 0 0 3.141593 0 0</pose>
        <always_on>1</always_on>
        <update_rate>1000.0</update_rate>
      </sensor>
    </link>
    <joint name='imu_joint' type='revolute'>
      <child>imu_link</child>
      <parent>base_link</parent>
      <axis>
        <xyz>1 0 0</xyz>
        <limit>
          <lower>0</lower>
          <upper>0</upper>
          <effort>0</effort>
          <velocity>-10</velocity>
        </limit>
        <dynamics>
          <damping>1.0</damping>
        </dynamics>
        <use_parent_model_frame>1</use_parent_model_frame>
      </axis>
    </joint>

    <joint name='rotor_1_joint' type='revolute'>
      <parent>servo_link</parent>
      <child>rotor_1</child>
      <pose>-0 0 0 0 -0 0</pose>
      <axis>
        <xyz>0 0 1</xyz>
        <limit>
          <lower>-1e+16</lower>
          <upper>1e+16</upper>
          <effort>-1</effort>
          <velocity>-10</velocity>
        </limit>
        <dynamics>
          <spring_reference>0</spring_reference>
          <spring_stiffness>0</spring_stiffness>
          <damping>0</damping>
          <friction>0</friction>
        </dynamics>
      </axis>
      <physics>
        <ode>
          <limit>
            <cfm>0</cfm>
            <erp>0.2</erp>
          </limit>
          <suspension>
            <cfm>0</cfm>
            <erp>0.2</erp>
          </suspension>
        </ode>
      </physics>
    </joint>
    <joint name='rotor_2_joint' type='revolute'>
      <parent>base_link</parent>
      <child>rotor_2</child>
      <pose>0 0 0 0 -0 0</pose>
      <axis>
        <xyz>0 0 1</xyz>
        <limit>
          <lower>-1e+16</lower>
          <upper>1e+16</upper>
          <effort>-1</effort>
          <velocity>-10</velocity>
        </limit>
        <dynamics>
          <spring_reference>0</spring_reference>
          <spring_stiffness>0</spring_stiffness>
          <damping>0</damping>
          <friction>0</friction>
        </dynamics>
      </axis>
      <physics>
        <ode>
          <limit>
            <cfm>0</cfm>
            <erp>0.2</erp>
          </limit>
          <suspension>
            <cfm>0</cfm>
            <erp>0.2</erp>
          </suspension>
        </ode>
      </physics>
    </joint>
    <joint name='rotor_3_joint' type='revolute'>
      <parent>base_link</parent>
      <child>rotor_3</child>
      <pose>0 0 0 0 -0 0</pose>
      <axis>
        <xyz>0 0 1</xyz>
        <limit>
          <lower>-1e+16</lower>
          <upper>1e+16</upper>
          <effort>-1</effort>
          <velocity>-10</velocity>
        </limit>
        <dynamics>
          <spring_reference>0</spring_reference>
          <spring_stiffness>0</spring_stiffness>
          <damping>0</damping>
          <friction>0</friction>
        </dynamics>
      </axis>
      <physics>
        <ode>
          <limit>
            <cfm>0</cfm>
            <erp>0.2</erp>
          </limit>
          <suspension>
            <cfm>0</cfm>
            <erp>0.2</erp>
          </suspension>
        </ode>
      </physics>
    </joint>
    <joint name='rotor_4_joint' type='revolute'>
      <parent>base_link</parent>
      <child>rotor_4</child>
      <pose>-0 0 0 0 -0 0</pose>
      <axis>
        <xyz>0 0 1</xyz>
        <limit>
          <lower>-1e+16</lower>
          <upper>1e+16</upper>
          <effort>-1</effort>
          <velocity>-10</velocity>
        </limit>
        <dynamics>
          <spring_reference>0</spring_reference>
          <spring_stiffness>0</spring_stiffness>
          <damping>0</damping>
          <friction>0</friction>
        </dynamics>
      </axis>
      <physics>
        <ode>
          <limit>
            <cfm>0</cfm>
            <erp>0.2</erp>
          </limit>
          <suspension>
            <cfm>0</cfm>
            <erp>0.2</erp>
          </suspension>
        </ode>
      </physics>
    </joint>
    <joint name='rotor_5_joint' type='revolute'>
      <parent>base_link</parent>
      <child>rotor_5</child>
      <pose>0 0 0 0 -0 0</pose>
      <axis>
        <xyz>0 0 1</xyz>
        <limit>
          <lower>-1e+16</lower>
          <upper>1e+16</upper>
          <effort>-1</effort>
          <velocity>-10</velocity>
        </limit>
        <dynamics>
          <spring_reference>0</spring_reference>
          <spring_stiffness>0</spring_stiffness>
          <damping>0</damping>
          <friction>0</friction>
        </dynamics>
      </axis>
      <physics>
        <ode>
          <limit>
            <cfm>0</cfm>
            <erp>0.2</erp>
          </limit>
          <suspension>
            <cfm>0</cfm>
            <erp>0.2</erp>
          </suspension>
        </ode>
      </physics>
    </joint>
    <joint name='rotor_6_joint' type='revolute'>
      <parent>base_link</parent>
      <child>rotor_6</child>
      <pose>0 -0 0 0 -0 0</pose>
      <axis>
        <xyz>0 0 1</xyz>
        <limit>
          <lower>-1e+16</lower>
          <upper>1e+16</upper>
          <effort>-1</effort>
          <velocity>-10</velocity>
        </limit>
        <dynamics>
          <spring_reference>0</spring_reference>
          <spring_stiffness>0</spring_stiffness>
          <damping>0</damping>
          <friction>0</friction>
        </dynamics>
      </axis>
      <physics>
        <ode>
          <limit>
            <cfm>0</cfm>
            <erp>0.2</erp>
          </limit>
          <suspension>
            <cfm>0</cfm>
            <erp>0.2</erp>
          </suspension>
        </ode>
      </physics>
    </joint>



    <link name='servo_link'>
    <pose>-0 0.2809 0.024 1.5708 -0 0</pose>
      <inertial>
        <pose>-0 0 0 0 -0 0</pose>
        <mass>0.002457</mass>
        <inertia>
          <ixx>0.0347563</ixx>
          <iyz>0.000001</iyz>
          <iyz>0.000001</iyz>
          <iyy>0.0458929</iyy>
          <iyz>0.000001</iyz>
          <izz>0.1</izz>
        </inertia>
      </inertial>
      <self_collide>0</self_collide>
      <enable_wind>0</enable_wind>
      <kinematic>0</kinematic>
      <visual name='servo_link_visual'>
        <pose>0 0 0 0 -0 0</pose>
        <geometry>
          <mesh>
            <scale>1 1 1</scale>
            <uri>/home/usr/catkin_ws/src/uav_simulator/uav_gazebo/meshes/servo_link.STL</uri>
          </mesh>
        </geometry>
        <material>
          <shader type='pixel'/>
          <emissive>0 0 0 1</emissive>
        </material>
        <transparency>0</transparency>
        <cast_shadows>1</cast_shadows>
      </visual>
      <collision name='servo_link_collision'>
        <laser_retro>0</laser_retro>
        <max_contacts>10</max_contacts>
        <pose>0 0 0 0 -0 0</pose>
        <geometry>
          <mesh>
            <uri>/home/usr/catkin_ws/src/uav_simulator/uav_gazebo/meshes/servo_link.STL</uri>
            <scale>1 1 1</scale>
          </mesh>
        </geometry>
        <surface>
          <friction>
            <ode>
              <mu>1</mu>
              <mu2>1</mu2>
              <fdir1>0 0 0</fdir1>
              <slip1>0</slip1>
              <slip2>0</slip2>
            </ode>
            <torsional>
              <coefficient>1</coefficient>
              <patch_radius>0</patch_radius>
              <surface_radius>0</surface_radius>
              <use_patch_radius>1</use_patch_radius>
              <ode>
                <slip>0</slip>
              </ode>
            </torsional>
          </friction>
          <bounce>
            <restitution_coefficient>0</restitution_coefficient>
            <threshold>1e+06</threshold>
          </bounce>
          <contact>
            <collide_without_contact>0</collide_without_contact>
            <collide_without_contact_bitmask>1</collide_without_contact_bitmask>
            <collide_bitmask>1</collide_bitmask>
            <ode>
              <soft_cfm>0</soft_cfm>
              <soft_erp>0.2</soft_erp>
              <kp>1e+13</kp>
              <kd>1</kd>
              <max_vel>0.01</max_vel>
              <min_depth>0</min_depth>
            </ode>
            <bullet>
              <split_impulse>1</split_impulse>
              <split_impulse_penetration_threshold>-0.01</split_impulse_penetration_threshold>
              <soft_cfm>0</soft_cfm>
              <soft_erp>0.2</soft_erp>
              <kp>1e+13</kp>
              <kd>1</kd>
            </bullet>
          </contact>
        </surface>
      </collision>
    </link>
    <joint name='servo_joint' type='revolute'>
      <parent>base_link</parent>
      <child>servo_link</child>
      <pose>-0 -0 0 0 -0 0</pose>
      <axis>
        <xyz>0 0 1 </xyz>
        <limit>
          <lower>-1e+16</lower>
          <upper>1e+16</upper>
          <effort>-10</effort>
          <velocity>0</velocity>
        </limit>
        <dynamics>
          <spring_reference>0</spring_reference>
          <spring_stiffness>0</spring_stiffness>
          <damping>0</damping>
          <friction>0</friction>
        </dynamics>
      </axis>
      <physics>
        <ode>
          <limit>
            <cfm>0</cfm>
            <erp>0</erp>
          </limit>
          <suspension>
            <cfm>0</cfm>
            <erp>0</erp>
          </suspension>
        </ode>
      </physics>
    </joint>

    
    
    <!-- <include>
      <uri>model://sonar</uri>
    </include>
    <joint name="sonar_joint" type="revolute">
      <child>sonar_model::link</child>
      <parent>typhoon_h480::base_link</parent>
      <axis>
        <xyz>0 0 1</xyz>
        <limit>
          <upper>0</upper>
          <lower>0</lower>
        </limit>
      </axis>
    </joint> -->

    <!-- plugins -->
    <plugin name="rotor_1_blade_1" filename="libLiftDragPlugin.so">
      <a0>0.3</a0>
      <alpha_stall>1.4</alpha_stall>
      <cla>4.500</cla>
      <cda>0.10</cda>
      <cma>0.00</cma>
      <cla_stall>-0.025</cla_stall>
      <cda_stall>0.0</cda_stall>
      <cma_stall>0.0</cma_stall>
      <area>0.002</area>
      <air_density>1.2041</air_density>
      <cp>0.0 0.084 0</cp>
      <forward>1 0 0</forward>
      <upward>0 0 1</upward>
      <link_name>rotor_1</link_name>
    </plugin>
    <plugin name="rotor_1_blade_2" filename="libLiftDragPlugin.so">
      <a0>0.3</a0>
      <alpha_stall>1.4</alpha_stall>
      <cla>4.500</cla>
      <cda>0.10</cda>
      <cma>0.00</cma>
      <cla_stall>-0.025</cla_stall>
      <cda_stall>0.0</cda_stall>
      <cma_stall>0.0</cma_stall>
      <area>0.002</area>
      <air_density>1.2041</air_density>
      <cp>0.0 -0.084 0</cp>
      <forward>-1 0 0</forward>
      <upward>0 0 1</upward>
      <link_name>rotor_1</link_name>
    </plugin>

    <plugin name="rotor_2_blade_1" filename="libLiftDragPlugin.so">
      <a0>0.3</a0>
      <alpha_stall>1.4</alpha_stall>
      <cla>4.500</cla>
      <cda>0.10</cda>
      <cma>0.00</cma>
      <cla_stall>-0.025</cla_stall>
      <cda_stall>0.0</cda_stall>
      <cma_stall>0.0</cma_stall>
      <area>0.002</area>
      <air_density>1.2041</air_density>
      <cp>0.0 0.084 0</cp>
      <forward>-1 0 0</forward>
      <upward>0 0 1</upward>
      <link_name>rotor_2</link_name>
    </plugin>

    <plugin name="rotor_2_blade_2" filename="libLiftDragPlugin.so">
      <a0>0.3</a0>
      <alpha_stall>1.4</alpha_stall>
      <cla>4.500</cla>
      <cda>0.10</cda>
      <cma>0.00</cma>
      <cla_stall>-0.025</cla_stall>
      <cda_stall>0.0</cda_stall>
      <cma_stall>0.0</cma_stall>
      <area>0.002</area>
      <air_density>1.2041</air_density>
      <cp>0.0 -0.084 0</cp>
      <forward>1 0 0</forward>
      <upward>0 0 1</upward>
      <link_name>rotor_2</link_name>
    </plugin>

    <plugin name="rotor_3_blade_1" filename="libLiftDragPlugin.so">
      <a0>0.3</a0>
      <alpha_stall>1.4</alpha_stall>
      <cla>4.500</cla>
      <cda>0.10</cda>
      <cma>0.00</cma>
      <cla_stall>-0.025</cla_stall>
      <cda_stall>0.0</cda_stall>
      <cma_stall>0.0</cma_stall>
      <area>0.002</area>
      <air_density>1.2041</air_density>
      <cp>0.0 0.084 0</cp>
      <forward>1 0 0</forward>
      <upward>0 0 1</upward>
      <link_name>rotor_3</link_name>
    </plugin>
    <plugin name="rotor_3_blade_2" filename="libLiftDragPlugin.so">
      <a0>0.3</a0>
      <alpha_stall>1.4</alpha_stall>
      <cla>4.500</cla>
      <cda>0.10</cda>
      <cma>0.00</cma>
      <cla_stall>-0.025</cla_stall>
      <cda_stall>0.0</cda_stall>
      <cma_stall>0.0</cma_stall>
      <area>0.002</area>
      <air_density>1.2041</air_density>
      <cp>0.0 -0.084 0</cp>
      <forward>-1 0 0</forward>
      <upward>0 0 1</upward>
      <link_name>rotor_3</link_name>
    </plugin>

    <plugin name="rotor_4_blade_1" filename="libLiftDragPlugin.so">
      <a0>0.3</a0>
      <alpha_stall>1.4</alpha_stall>
      <cla>4.500</cla>
      <cda>0.10</cda>
      <cma>0.00</cma>
      <cla_stall>-0.025</cla_stall>
      <cda_stall>0.0</cda_stall>
      <cma_stall>0.0</cma_stall>
      <area>0.002</area>
      <air_density>1.2041</air_density>
      <cp>0.0 0.084 0</cp>
      <forward>1 0 0</forward>
      <upward>0 0 1</upward>
      <link_name>rotor_4</link_name>
    </plugin>
    <plugin name="rotor_4_blade_2" filename="libLiftDragPlugin.so">
      <a0>0.3</a0>
      <alpha_stall>1.4</alpha_stall>
      <cla>4.500</cla>
      <cda>0.10</cda>
      <cma>0.00</cma>
      <cla_stall>-0.025</cla_stall>
      <cda_stall>0.0</cda_stall>
      <cma_stall>0.0</cma_stall>
      <area>0.002</area>
      <air_density>1.2041</air_density>
      <cp>0.0 -0.084 0</cp>
      <forward>-1 0 0</forward>
      <upward>0 0 1</upward>
      <link_name>rotor_4</link_name>
    </plugin>

    <plugin name="rotor_5_blade_1" filename="libLiftDragPlugin.so">
      <a0>0.3</a0>
      <alpha_stall>1.4</alpha_stall>
      <cla>4.500</cla>
      <cda>0.10</cda>
      <cma>0.00</cma>
      <cla_stall>-0.025</cla_stall>
      <cda_stall>0.0</cda_stall>
      <cma_stall>0.0</cma_stall>
      <area>0.002</area>
      <air_density>1.2041</air_density>
      <cp>0.0 0.084 0</cp>
      <forward>-1 0 0</forward>
      <upward>0 0 1</upward>
      <link_name>rotor_5</link_name>
    </plugin>
    <plugin name="rotor_5_blade_2" filename="libLiftDragPlugin.so">
      <a0>0.3</a0>
      <alpha_stall>1.4</alpha_stall>
      <cla>4.500</cla>
      <cda>0.10</cda>
      <cma>0.00</cma>
      <cla_stall>-0.025</cla_stall>
      <cda_stall>0.0</cda_stall>
      <cma_stall>0.0</cma_stall>
      <area>0.002</area>
      <air_density>1.2041</air_density>
      <cp>0.0 -0.084 0</cp>
      <forward>1 0 0</forward>
      <upward>0 0 1</upward>
      <link_name>rotor_5</link_name>
    </plugin>

    <plugin name="rotor_6_blade_1" filename="libLiftDragPlugin.so">
      <a0>0.3</a0>
      <alpha_stall>1.4</alpha_stall>
      <cla>4.500</cla>
      <cda>0.10</cda>
      <cma>0.00</cma>
      <cla_stall>-0.025</cla_stall>
      <cda_stall>0.0</cda_stall>
      <cma_stall>0.0</cma_stall>
      <area>0.002</area>
      <air_density>1.2041</air_density>
      <cp>0.0 0.084 0</cp>
      <forward>-1 0 0</forward>
      <upward>0 0 1</upward>
      <link_name>rotor_6</link_name>
    </plugin>
    <plugin name="rotor_6_blade_2" filename="libLiftDragPlugin.so">
      <a0>0.3</a0>
      <alpha_stall>1.4</alpha_stall>
      <cla>4.500</cla>
      <cda>0.10</cda>
      <cma>0.00</cma>
      <cla_stall>-0.025</cla_stall>
      <cda_stall>0.0</cda_stall>
      <cma_stall>0.0</cma_stall>
      <area>0.002</area>
      <air_density>1.2041</air_density>
      <cp>0.0 -0.084 0</cp>
      <forward>1 0 0</forward>
      <upward>0 0 1</upward>
      <link_name>rotor_6</link_name>
    </plugin>

    


    <plugin name="ArduCopter_Plugin" filename="libArduPilotPlugin.so">
      <fdm_addr>127.0.0.1</fdm_addr>
      <fdm_port_in>9002</fdm_port_in>
      <fdm_port_out>9003</fdm_port_out>
      <!--
          Require by APM :
          Only change model and gazebo from XYZ to XY-Z coordinates
      -->
      <!-- 3.141593 -->
      <modelXYZToAirplaneXForwardZDown>0 0 0 3.141593 0 3.141593</modelXYZToAirplaneXForwardZDown>
      <gazeboXYZToNED>0 0 0 3.141593 0 3.141593</gazeboXYZToNED>
      <imuName>myhexa::imu_link::imu_sensor</imuName>
      <connectionTimeoutMaxCount>5</connectionTimeoutMaxCount>
      <!--
          incoming control command [0, 1]
          so offset it by 0 to get [0, 1]
          and divide max target by 1.
          offset = 0
          multiplier = 838 max rpm / 1 = 838
        -->
      <control channel="0">
        <type>VELOCITY</type>
        <offset>0</offset>
        <p_gain>0.20</p_gain>
        <i_gain>0</i_gain>
        <d_gain>0</d_gain>
        <i_max>0</i_max>
        <i_min>0</i_min>
        <cmd_max>2.5</cmd_max>
        <cmd_min>-2.5</cmd_min>
        <jointName>rotor_1_joint</jointName>
        <multiplier>-1200</multiplier>
        <controlVelocitySlowdownSim>1</controlVelocitySlowdownSim>
      </control>
      <control channel="1">
        <type>VELOCITY</type>
        <offset>0</offset>
        <p_gain>0.20</p_gain>
        <i_gain>0</i_gain>
        <d_gain>0</d_gain>
        <i_max>0</i_max>
        <i_min>0</i_min>
        <cmd_max>2.5</cmd_max>
        <cmd_min>-2.5</cmd_min>
        <jointName>rotor_2_joint</jointName>
        <multiplier>1200</multiplier>
        <controlVelocitySlowdownSim>1</controlVelocitySlowdownSim>
      </control>
<!--///////////////////////////////////////////////////////////////////////////////////////////
                         3 \ +5° 990
///////////////////////////////////////////////////////////////////////////////////////////////-->
      <!-- <control channel="2">
        <type>VELOCITY</type>
        <offset>0</offset>
        <p_gain>0.20</p_gain>
        <i_gain>0</i_gain>
        <d_gain>0</d_gain>
        <i_max>0</i_max>
        <i_min>0</i_min>
        <cmd_max>2.5</cmd_max>
        <cmd_min>-2.5</cmd_min>
        <jointName>rotor_3_joint</jointName>
        <multiplier>-1200</multiplier>
        <controlVelocitySlowdownSim>1</controlVelocitySlowdownSim>
      </control> -->
      <control channel="3">
        <type>VELOCITY</type>
        <offset>0</offset>
        <p_gain>0.20</p_gain>
        <i_gain>0</i_gain>
        <d_gain>0</d_gain>
        <i_max>0</i_max>
        <i_min>0</i_min>
        <cmd_max>2.5</cmd_max>
        <cmd_min>-2.5</cmd_min>
        <jointName>rotor_4_joint</jointName>
        <multiplier>-1200</multiplier>
        <controlVelocitySlowdownSim>1</controlVelocitySlowdownSim>
<!--///////////////////////////////////////////////////////////////////////////////////////////
                         5 \ -5° 1010
///////////////////////////////////////////////////////////////////////////////////////////////-->
      <control channel="4">
        <type>VELOCITY</type>
        <offset>0</offset>
        <p_gain>0.20</p_gain>
        <i_gain>0</i_gain>
        <d_gain>0</d_gain>
        <i_max>0</i_max>
        <i_min>0</i_min>
        <cmd_max>2.5</cmd_max>
        <cmd_min>-2.5</cmd_min>
        <jointName>rotor_5_joint</jointName>
        <multiplier>1200</multiplier>
        <controlVelocitySlowdownSim>1</controlVelocitySlowdownSim>
      </control>
      <control channel="5">
        <type>VELOCITY</type>
        <offset>0</offset>
        <p_gain>0.20</p_gain>
        <i_gain>0</i_gain>
        <d_gain>0</d_gain>
        <i_max>0</i_max>
        <i_min>0</i_min>
        <cmd_max>2.5</cmd_max>
        <cmd_min>-2.5</cmd_min>
        <jointName>rotor_6_joint</jointName>
        <multiplier>1200</multiplier>
        <controlVelocitySlowdownSim>1</controlVelocitySlowdownSim>
      </control>
      <control channel="6">
        <offset>0</offset>
        <type>POSITION</type>
        <p_gain>1000</p_gain>
        <i_gain>0</i_gain>
        <d_gain>0</d_gain>
        <jointName>servo_joint</jointName>
        <multiplier>-1</multiplier>
        <controlVelocitySlowdownSim>1</controlVelocitySlowdownSim>
      </control>
      </plugin>
  <static>0</static>
  </model>
</sdf>
